INFO 2025-08-16 01:57:50,508 autoreload 50093 8431274048 Watching for file changes with StatReloader
INFO 2025-08-16 02:02:19,076 autoreload 50093 8431274048 /Users/mac/Desktop/CODE/AI-Launch-Pad/backend/AI_Launch_Pad/core/models.py changed, reloading.
INFO 2025-08-16 02:02:19,605 autoreload 50165 8431274048 Watching for file changes with StatReloader
INFO 2025-08-16 02:02:30,116 autoreload 50165 8431274048 /Users/mac/Desktop/CODE/AI-Launch-Pad/backend/AI_Launch_Pad/AI_Launch_Pad/urls.py changed, reloading.
INFO 2025-08-16 02:02:30,596 autoreload 50182 8431274048 Watching for file changes with StatReloader
INFO 2025-08-16 02:04:39,921 autoreload 50932 8431274048 Watching for file changes with StatReloader
INFO 2025-08-16 02:08:08,515 autoreload 50932 8431274048 /Users/mac/Desktop/CODE/AI-Launch-Pad/backend/venv/lib/python3.11/site-packages/eth_rlp/main.py changed, reloading.
INFO 2025-08-16 02:08:09,140 autoreload 51684 8431274048 Watching for file changes with StatReloader
INFO 2025-08-16 02:09:09,702 basehttp 51684 6192754688 "GET /health HTTP/1.1" 301 0
INFO 2025-08-16 18:06:57,522 autoreload 60102 8431274048 Watching for file changes with StatReloader
ERROR 2025-08-16 18:07:01,055 log 60102 6190985216 Internal Server Error: /health/
Traceback (most recent call last):
  File "/Users/mac/Desktop/CODE/AI-Launch-Pad/backend/venv/lib/python3.11/site-packages/django_redis/cache.py", line 29, in _decorator
    return method(self, *args, **kwargs)
           ^^^^^^^^^^^^^^^^^^^^^^^^^^^^^
  File "/Users/mac/Desktop/CODE/AI-Launch-Pad/backend/venv/lib/python3.11/site-packages/django_redis/cache.py", line 99, in _get
    return self.client.get(key, default=default, version=version, client=client)
           ^^^^^^^^^^^^^^^^^^^^^^^^^^^^^^^^^^^^^^^^^^^^^^^^^^^^^^^^^^^^^^^^^^^^^
  File "/Users/mac/Desktop/CODE/AI-Launch-Pad/backend/venv/lib/python3.11/site-packages/django_redis/client/default.py", line 260, in get
    raise ConnectionInterrupted(connection=client) from e
django_redis.exceptions.ConnectionInterrupted: Redis ConnectionError: Error 61 connecting to localhost:6379. Connection refused.

During handling of the above exception, another exception occurred:

Traceback (most recent call last):
  File "/Users/mac/Desktop/CODE/AI-Launch-Pad/backend/venv/lib/python3.11/site-packages/django/core/handlers/exception.py", line 55, in inner
    response = get_response(request)
               ^^^^^^^^^^^^^^^^^^^^^
  File "/Users/mac/Desktop/CODE/AI-Launch-Pad/backend/venv/lib/python3.11/site-packages/django/core/handlers/base.py", line 197, in _get_response
    response = wrapped_callback(request, *callback_args, **callback_kwargs)
               ^^^^^^^^^^^^^^^^^^^^^^^^^^^^^^^^^^^^^^^^^^^^^^^^^^^^^^^^^^^^
  File "/Users/mac/Desktop/CODE/AI-Launch-Pad/backend/venv/lib/python3.11/site-packages/django/views/decorators/csrf.py", line 56, in wrapper_view
    return view_func(*args, **kwargs)
           ^^^^^^^^^^^^^^^^^^^^^^^^^^
  File "/Users/mac/Desktop/CODE/AI-Launch-Pad/backend/venv/lib/python3.11/site-packages/django/views/generic/base.py", line 104, in view
    return self.dispatch(request, *args, **kwargs)
           ^^^^^^^^^^^^^^^^^^^^^^^^^^^^^^^^^^^^^^^
  File "/Users/mac/Desktop/CODE/AI-Launch-Pad/backend/venv/lib/python3.11/site-packages/rest_framework/views.py", line 509, in dispatch
    response = self.handle_exception(exc)
               ^^^^^^^^^^^^^^^^^^^^^^^^^^
  File "/Users/mac/Desktop/CODE/AI-Launch-Pad/backend/venv/lib/python3.11/site-packages/rest_framework/views.py", line 469, in handle_exception
    self.raise_uncaught_exception(exc)
  File "/Users/mac/Desktop/CODE/AI-Launch-Pad/backend/venv/lib/python3.11/site-packages/rest_framework/views.py", line 480, in raise_uncaught_exception
    raise exc
  File "/Users/mac/Desktop/CODE/AI-Launch-Pad/backend/venv/lib/python3.11/site-packages/rest_framework/views.py", line 497, in dispatch
    self.initial(request, *args, **kwargs)
  File "/Users/mac/Desktop/CODE/AI-Launch-Pad/backend/venv/lib/python3.11/site-packages/rest_framework/views.py", line 416, in initial
    self.check_throttles(request)
  File "/Users/mac/Desktop/CODE/AI-Launch-Pad/backend/venv/lib/python3.11/site-packages/rest_framework/views.py", line 359, in check_throttles
    if not throttle.allow_request(request, self):
           ^^^^^^^^^^^^^^^^^^^^^^^^^^^^^^^^^^^^^
  File "/Users/mac/Desktop/CODE/AI-Launch-Pad/backend/venv/lib/python3.11/site-packages/rest_framework/throttling.py", line 123, in allow_request
    self.history = self.cache.get(self.key, [])
                   ^^^^^^^^^^^^^^^^^^^^^^^^^^^^
  File "/Users/mac/Desktop/CODE/AI-Launch-Pad/backend/venv/lib/python3.11/site-packages/django_redis/cache.py", line 92, in get
    value = self._get(key, default, version, client)
            ^^^^^^^^^^^^^^^^^^^^^^^^^^^^^^^^^^^^^^^^
  File "/Users/mac/Desktop/CODE/AI-Launch-Pad/backend/venv/lib/python3.11/site-packages/django_redis/cache.py", line 36, in _decorator
    raise e.__cause__
  File "/Users/mac/Desktop/CODE/AI-Launch-Pad/backend/venv/lib/python3.11/site-packages/django_redis/client/default.py", line 258, in get
    value = client.get(key)
            ^^^^^^^^^^^^^^^
  File "/Users/mac/Desktop/CODE/AI-Launch-Pad/backend/venv/lib/python3.11/site-packages/redis/commands/core.py", line 1829, in get
    return self.execute_command("GET", name)
           ^^^^^^^^^^^^^^^^^^^^^^^^^^^^^^^^^
  File "/Users/mac/Desktop/CODE/AI-Launch-Pad/backend/venv/lib/python3.11/site-packages/redis/client.py", line 505, in execute_command
    conn = self.connection or pool.get_connection(command_name, **options)
                              ^^^^^^^^^^^^^^^^^^^^^^^^^^^^^^^^^^^^^^^^^^^^
  File "/Users/mac/Desktop/CODE/AI-Launch-Pad/backend/venv/lib/python3.11/site-packages/redis/connection.py", line 1073, in get_connection
    connection.connect()
  File "/Users/mac/Desktop/CODE/AI-Launch-Pad/backend/venv/lib/python3.11/site-packages/redis/connection.py", line 265, in connect
    raise ConnectionError(self._error_message(e))
redis.exceptions.ConnectionError: Error 61 connecting to localhost:6379. Connection refused.
ERROR 2025-08-16 18:07:01,057 basehttp 60102 6190985216 "GET /health/ HTTP/1.1" 500 147400
INFO 2025-08-16 18:07:01,057 basehttp 60102 6190985216 - Broken pipe from ('127.0.0.1', 58120)
INFO 2025-08-16 18:09:43,256 autoreload 60102 8431274048 /Users/mac/Desktop/CODE/AI-Launch-Pad/backend/AI_Launch_Pad/AI_Launch_Pad/settings.py changed, reloading.
INFO 2025-08-16 18:09:43,820 autoreload 60469 8431274048 Watching for file changes with StatReloader
INFO 2025-08-16 18:09:52,520 autoreload 60469 8431274048 /Users/mac/Desktop/CODE/AI-Launch-Pad/backend/AI_Launch_Pad/AI_Launch_Pad/urls.py changed, reloading.
INFO 2025-08-16 18:09:52,991 autoreload 60488 8431274048 Watching for file changes with StatReloader
INFO 2025-08-16 18:10:19,118 autoreload 60488 8431274048 /Users/mac/Desktop/CODE/AI-Launch-Pad/backend/AI_Launch_Pad/AI_Launch_Pad/urls.py changed, reloading.
INFO 2025-08-16 18:10:19,657 autoreload 60499 8431274048 Watching for file changes with StatReloader
INFO 2025-08-16 18:12:59,091 autoreload 61471 8431274048 Watching for file changes with StatReloader
INFO 2025-08-16 18:13:57,917 basehttp 60499 6137163776 "GET /health/ HTTP/1.1" 200 52
INFO 2025-08-16 18:14:20,091 basehttp 60499 6137163776 "GET /health/ HTTP/1.1" 200 52
INFO 2025-08-16 18:24:51,783 basehttp 60499 6137163776 "OPTIONS /api/auth/web3/nonce/ HTTP/1.1" 200 0
INFO 2025-08-16 18:24:51,836 basehttp 60499 6137163776 "POST /api/auth/web3/nonce/ HTTP/1.1" 200 44
INFO 2025-08-16 18:24:54,003 basehttp 60499 6137163776 "OPTIONS /api/auth/web3/verify/ HTTP/1.1" 200 0
INFO 2025-08-16 18:24:56,614 basehttp 60499 6137163776 "POST /api/auth/web3/verify/ HTTP/1.1" 200 52
INFO 2025-08-16 18:25:08,336 basehttp 60499 6137163776 "OPTIONS /api/launches/ HTTP/1.1" 200 0
ERROR 2025-08-16 18:25:08,385 log 60499 6137163776 Internal Server Error: /api/launches/
Traceback (most recent call last):
  File "/Users/mac/Desktop/CODE/AI-Launch-Pad/backend/venv/lib/python3.11/site-packages/django/db/backends/utils.py", line 89, in _execute
    return self.cursor.execute(sql, params)
           ^^^^^^^^^^^^^^^^^^^^^^^^^^^^^^^^
  File "/Users/mac/Desktop/CODE/AI-Launch-Pad/backend/venv/lib/python3.11/site-packages/django/db/backends/sqlite3/base.py", line 328, in execute
    return super().execute(query, params)
           ^^^^^^^^^^^^^^^^^^^^^^^^^^^^^^
sqlite3.IntegrityError: NOT NULL constraint failed: token_launches.category_id

The above exception was the direct cause of the following exception:

Traceback (most recent call last):
  File "/Users/mac/Desktop/CODE/AI-Launch-Pad/backend/venv/lib/python3.11/site-packages/django/core/handlers/exception.py", line 55, in inner
    response = get_response(request)
               ^^^^^^^^^^^^^^^^^^^^^
  File "/Users/mac/Desktop/CODE/AI-Launch-Pad/backend/venv/lib/python3.11/site-packages/django/core/handlers/base.py", line 197, in _get_response
    response = wrapped_callback(request, *callback_args, **callback_kwargs)
               ^^^^^^^^^^^^^^^^^^^^^^^^^^^^^^^^^^^^^^^^^^^^^^^^^^^^^^^^^^^^
  File "/Users/mac/Desktop/CODE/AI-Launch-Pad/backend/venv/lib/python3.11/site-packages/django/views/decorators/csrf.py", line 56, in wrapper_view
    return view_func(*args, **kwargs)
           ^^^^^^^^^^^^^^^^^^^^^^^^^^
  File "/Users/mac/Desktop/CODE/AI-Launch-Pad/backend/venv/lib/python3.11/site-packages/django/views/generic/base.py", line 104, in view
    return self.dispatch(request, *args, **kwargs)
           ^^^^^^^^^^^^^^^^^^^^^^^^^^^^^^^^^^^^^^^
  File "/Users/mac/Desktop/CODE/AI-Launch-Pad/backend/venv/lib/python3.11/site-packages/rest_framework/views.py", line 509, in dispatch
    response = self.handle_exception(exc)
               ^^^^^^^^^^^^^^^^^^^^^^^^^^
  File "/Users/mac/Desktop/CODE/AI-Launch-Pad/backend/venv/lib/python3.11/site-packages/rest_framework/views.py", line 469, in handle_exception
    self.raise_uncaught_exception(exc)
  File "/Users/mac/Desktop/CODE/AI-Launch-Pad/backend/venv/lib/python3.11/site-packages/rest_framework/views.py", line 480, in raise_uncaught_exception
    raise exc
  File "/Users/mac/Desktop/CODE/AI-Launch-Pad/backend/venv/lib/python3.11/site-packages/rest_framework/views.py", line 506, in dispatch
    response = handler(request, *args, **kwargs)
               ^^^^^^^^^^^^^^^^^^^^^^^^^^^^^^^^^
  File "/Users/mac/Desktop/CODE/AI-Launch-Pad/backend/venv/lib/python3.11/site-packages/rest_framework/decorators.py", line 50, in handler
    return func(*args, **kwargs)
           ^^^^^^^^^^^^^^^^^^^^^
  File "/Users/mac/Desktop/CODE/AI-Launch-Pad/backend/AI_Launch_Pad/AI_Launch_Pad/urls.py", line 45, in launches
    launch = TokenLaunch.objects.create(
             ^^^^^^^^^^^^^^^^^^^^^^^^^^^
  File "/Users/mac/Desktop/CODE/AI-Launch-Pad/backend/venv/lib/python3.11/site-packages/django/db/models/manager.py", line 87, in manager_method
    return getattr(self.get_queryset(), name)(*args, **kwargs)
           ^^^^^^^^^^^^^^^^^^^^^^^^^^^^^^^^^^^^^^^^^^^^^^^^^^^
  File "/Users/mac/Desktop/CODE/AI-Launch-Pad/backend/venv/lib/python3.11/site-packages/django/db/models/query.py", line 658, in create
    obj.save(force_insert=True, using=self.db)
  File "/Users/mac/Desktop/CODE/AI-Launch-Pad/backend/venv/lib/python3.11/site-packages/django/db/models/base.py", line 814, in save
    self.save_base(
  File "/Users/mac/Desktop/CODE/AI-Launch-Pad/backend/venv/lib/python3.11/site-packages/django/db/models/base.py", line 877, in save_base
    updated = self._save_table(
              ^^^^^^^^^^^^^^^^^
  File "/Users/mac/Desktop/CODE/AI-Launch-Pad/backend/venv/lib/python3.11/site-packages/django/db/models/base.py", line 1020, in _save_table
    results = self._do_insert(
              ^^^^^^^^^^^^^^^^
  File "/Users/mac/Desktop/CODE/AI-Launch-Pad/backend/venv/lib/python3.11/site-packages/django/db/models/base.py", line 1061, in _do_insert
    return manager._insert(
           ^^^^^^^^^^^^^^^^
  File "/Users/mac/Desktop/CODE/AI-Launch-Pad/backend/venv/lib/python3.11/site-packages/django/db/models/manager.py", line 87, in manager_method
    return getattr(self.get_queryset(), name)(*args, **kwargs)
           ^^^^^^^^^^^^^^^^^^^^^^^^^^^^^^^^^^^^^^^^^^^^^^^^^^^
  File "/Users/mac/Desktop/CODE/AI-Launch-Pad/backend/venv/lib/python3.11/site-packages/django/db/models/query.py", line 1805, in _insert
    return query.get_compiler(using=using).execute_sql(returning_fields)
           ^^^^^^^^^^^^^^^^^^^^^^^^^^^^^^^^^^^^^^^^^^^^^^^^^^^^^^^^^^^^^
  File "/Users/mac/Desktop/CODE/AI-Launch-Pad/backend/venv/lib/python3.11/site-packages/django/db/models/sql/compiler.py", line 1822, in execute_sql
    cursor.execute(sql, params)
  File "/Users/mac/Desktop/CODE/AI-Launch-Pad/backend/venv/lib/python3.11/site-packages/django/db/backends/utils.py", line 102, in execute
    return super().execute(sql, params)
           ^^^^^^^^^^^^^^^^^^^^^^^^^^^^
  File "/Users/mac/Desktop/CODE/AI-Launch-Pad/backend/venv/lib/python3.11/site-packages/django/db/backends/utils.py", line 67, in execute
    return self._execute_with_wrappers(
           ^^^^^^^^^^^^^^^^^^^^^^^^^^^^
  File "/Users/mac/Desktop/CODE/AI-Launch-Pad/backend/venv/lib/python3.11/site-packages/django/db/backends/utils.py", line 80, in _execute_with_wrappers
    return executor(sql, params, many, context)
           ^^^^^^^^^^^^^^^^^^^^^^^^^^^^^^^^^^^^
  File "/Users/mac/Desktop/CODE/AI-Launch-Pad/backend/venv/lib/python3.11/site-packages/django/db/backends/utils.py", line 84, in _execute
    with self.db.wrap_database_errors:
  File "/Users/mac/Desktop/CODE/AI-Launch-Pad/backend/venv/lib/python3.11/site-packages/django/db/utils.py", line 91, in __exit__
    raise dj_exc_value.with_traceback(traceback) from exc_value
  File "/Users/mac/Desktop/CODE/AI-Launch-Pad/backend/venv/lib/python3.11/site-packages/django/db/backends/utils.py", line 89, in _execute
    return self.cursor.execute(sql, params)
           ^^^^^^^^^^^^^^^^^^^^^^^^^^^^^^^^
  File "/Users/mac/Desktop/CODE/AI-Launch-Pad/backend/venv/lib/python3.11/site-packages/django/db/backends/sqlite3/base.py", line 328, in execute
    return super().execute(query, params)
           ^^^^^^^^^^^^^^^^^^^^^^^^^^^^^^
django.db.utils.IntegrityError: NOT NULL constraint failed: token_launches.category_id
ERROR 2025-08-16 18:25:08,388 basehttp 60499 6137163776 "POST /api/launches/ HTTP/1.1" 500 214961
INFO 2025-08-16 18:32:48,625 autoreload 60499 8431274048 /Users/mac/Desktop/CODE/AI-Launch-Pad/backend/AI_Launch_Pad/AI_Launch_Pad/urls.py changed, reloading.
INFO 2025-08-16 18:32:49,222 autoreload 62476 8431274048 Watching for file changes with StatReloader
INFO 2025-08-16 18:33:08,991 basehttp 62476 6203142144 "OPTIONS /api/launches/ HTTP/1.1" 200 0
INFO 2025-08-16 18:33:09,028 basehttp 62476 6203142144 "POST /api/launches/ HTTP/1.1" 201 45
INFO 2025-08-16 18:33:26,186 basehttp 62476 6203142144 "OPTIONS /api/launches/97dc37ed-a9bc-49af-9cb8-f17609f1df53/attach_tx/ HTTP/1.1" 200 0
INFO 2025-08-16 18:33:26,204 basehttp 62476 6203142144 "POST /api/launches/97dc37ed-a9bc-49af-9cb8-f17609f1df53/attach_tx/ HTTP/1.1" 200 188
INFO 2025-08-16 19:02:48,103 basehttp 62476 6203142144 "OPTIONS /api/launches/ HTTP/1.1" 200 0
INFO 2025-08-16 19:02:48,131 basehttp 62476 6203142144 "POST /api/launches/ HTTP/1.1" 201 45
INFO 2025-08-16 19:02:59,912 basehttp 62476 6203142144 "OPTIONS /api/launches/706c8c61-4a91-49f2-a330-2f5a7a565d46/attach_tx/ HTTP/1.1" 200 0
INFO 2025-08-16 19:02:59,937 basehttp 62476 6203142144 "POST /api/launches/706c8c61-4a91-49f2-a330-2f5a7a565d46/attach_tx/ HTTP/1.1" 200 188
INFO 2025-08-16 21:02:05,047 autoreload 62476 8431274048 /Users/mac/Desktop/CODE/AI-Launch-Pad/backend/AI_Launch_Pad/AI_Launch_Pad/settings.py changed, reloading.
INFO 2025-08-16 21:02:06,061 autoreload 65982 8431274048 Watching for file changes with StatReloader
